<?xml version="1.0" ?>
<!-- =================================================================================== -->
<!-- |    This document was autogenerated by xacro from robco19m.urdf.xacro            | -->
<!-- |    EDITING THIS FILE BY HAND IS NOT RECOMMENDED                                 | -->
<!-- =================================================================================== -->
<robot name="robco19m" xmlns:xacro="http://ros.org/wiki/xacro">
  <!-- Properties file for Robco19M robot -->
  <!-- Created by Stefan -->
  <!-- Service Robotics Group Bulgaria - Version 1.0 from Oct. 1th, 2018. -->
  <!-- robot constants -->
  <!-- Base deck box (imaginery box covering/including front and rear boxes
    and the axle between them)   -->
  <!--front_wheel_to_rear_wheel_axle_distance-->
  <!-- Total mobile base weight 4.2 kg weight, wheel weight 0.400 kg each, mobile base weight without wheels 2.6 kg -->
  <!-- in kg weight with battery & electronics inside -->
  <!-- Common materials file for Robco robot URDF.XACRO's -->
  <!-- Created by Stefan -->
  <!-- Service Robotics Group Bulgaria - Version 1.0 from Oct. 1th, 2018. -->
  <material name="black">
    <color rgba="0.0 0.0 0.0 1.0"/>
  </material>
  <material name="gray2">
    <color rgba="0.7 0.7 0.7 1.0"/>
  </material>
  <material name="darkgray2">
    <color rgba="0.3 0.3 0.3 1.0"/>
  </material>
  <material name="dark-grey">
    <color rgba=".2 .2 .2 1"/>
  </material>
  <material name="grey">
    <color rgba="0.2 0.2 0.2 1.0"/>
  </material>
  <!--<material name="grey">
    <color rgba=".6 .6 .6 1" />
  </material>-->
  <material name="blue">
    <color rgba="0.0 0.0 0.8 1.0"/>
  </material>
  <material name="green">
    <color rgba="0.0 0.8 0.0 1.0"/>
  </material>
  <material name="orange">
    <color rgba="1.0 0.423529411765 0.0392156862745 1.0"/>
  </material>
  <material name="brown">
    <color rgba="0.870588235294 0.811764705882 0.764705882353 1.0"/>
  </material>
  <material name="red">
    <color rgba="0.8 0.0 0.0 1.0"/>
  </material>
  <material name="white">
    <color rgba="1.0 1.0 1.0 1.0"/>
  </material>
  <material name="yellow">
    <color rgba=".9 .9 0 1"/>
  </material>
  <material name="yellow2">
    <color rgba="0.8 0.8 0.0 1.0"/>
  </material>
  <material name="cyan">
    <color rgba="0 1 1 1"/>
  </material>
  <material name="silver">
    <color rgba="0.8 0.8 0.8 1"/>
  </material>
  <!-- Common macros file for Robco robot URDF.XACRO's -->
  <!-- Created by Stefan -->
  <!-- Service Robotics Group Bulgaria - Version 1.0 from Oct. 1th, 2018. -->
  <!-- Macros file for Robco19M -->
  <!-- Created by Stefan -->
  <!-- Service Robotics Group Bulgaria - Version 1.0 from Oct. 1th, 2018. -->
  <!-- Robco 19M base description -->
  <!-- Created by Stefan -->
  <!-- Service Robotics Group Bulgaria - Version 2.0 from Oct. 1th, 2018. -->
  <!-- URDF file for the Commonplace Robotics Mover4 robot arm -->
  <!-- BAsed on the official Commonplace Robotics Version 1.1 of the file from Oct. 04th, 2016. -->
  <!-- Modified arm URDF to include a joint, which links the top plate of Robco19M (linorobot) to the base plate of the CPRMover4 arm:-->
  <!-- Version 2.0.1 from Sep. 10th, 2018. -->
  <!-- BASE FOOTPRINT -->
  <!-- base_footprint is a fictitious link(frame) that is on the ground right below base_link origin,
             navigation stack depends on this frame -->
  <!--<link name="base_footprint">
      <visual>
          <origin xyz="0 0 0" rpy="0 0 0" />
          <geometry>
             <box size="0.001 0.001 0.001" />
          </geometry>
      </visual>

      <collision>
          <origin xyz="0 0 0" rpy="0 0 0" />
          <geometry>
            <box size="0.001 0.001 0.001" />
         </geometry>
     </collision>
  </link>-->
  <!--NB: While you would think this would make it go up, it is oddly reversed.
      This moves the joint to 0,0,0 where we want it for rviz, etc. -->
  <!-- origin xyz="0 0 0.130" rpy="0 0 0" / -->
  <!--<origin xyz="0 0 0.18" rpy="0 0 0" />-->
  <!--<joint name="base_footprint_joint" type="fixed">  
     <origin xyz="0 0 ${base_Z_offset/10000}" rpy="0 0 0" />
     
     <parent link="base_footprint"/>
     <child link="base_link" />
  </joint>-->
  <!--#### CHASSIS ##############################################################################-->
  <!--
     base_link is defined as a point in the middle of the height of the metal base platform shell, in the crossing 
     between the imaginery line between the middle of the front left wheel and right rear wheel and 
     the imaginery line between front right wheel and rear left wheel (all this, looking from the top, 
     above the robot). 
  -->
  <link name="base_link">
    <!--<pose>0 0 0.1 0 0 0</pose>-->
    <inertial>
      <mass value="2.6"/>
      <origin rpy=" 0 0 0" xyz="0 0 0.051"/>
      <inertia ixx="0.1" ixy="0" ixz="0" iyy="0.1" iyz="0" izz="0.1"/>
    </inertial>
    <!--<collision name='collision'>-->
    <collision>
      <origin rpy=" 0 0 0" xyz="0 0 0.051"/>
      <geometry>
        <box size="0.218 0.054 0.39"/>
      </geometry>
    </collision>
    <!--<visual name='chassis_visual'>-->
    <visual>
      <origin rpy=" 0 0 0" xyz="0 0 0.051"/>
      <geometry>
        <box size="0.39 0.218 0.054"/>
      </geometry>
      <material name="yellow"/>
    </visual>
  </link>
  <!--#### END CHASSIS ##############################################################################-->
  <link name="left_front_wheel">
    <collision name="left_front_wheel_collision">
      <origin rpy="0 1.570796327 1.570796327" xyz="0 0 0"/>
      <geometry>
        <cylinder length="0.05" radius="0.05"/>
      </geometry>
    </collision>
    <visual name="left_front_wheel_visual">
      <origin rpy="0 1.570796327 1.570796327" xyz="0 0 0"/>
      <geometry>
        <cylinder length="0.05" radius="0.05"/>
      </geometry>
      <material name="silver"/>
    </visual>
    <inertial>
      <origin rpy="0 1.570796327 1.570796327" xyz="0 0 0"/>
      <mass value="0.4"/>
      <inertia ixx=".1" ixy="0.0" ixz="0.0" iyy=".1" iyz="0.0" izz=".1"/>
    </inertial>
  </link>
  <link name="left_rear_wheel">
    <collision name="left_rear_wheel_collision">
      <origin rpy="0 1.570796327 1.570796327" xyz="0 0 0"/>
      <geometry>
        <cylinder length="0.05" radius="0.05"/>
      </geometry>
    </collision>
    <visual name="left_rear_wheel_visual">
      <origin rpy="0 1.570796327 1.570796327" xyz="0 0 0"/>
      <geometry>
        <cylinder length="0.05" radius="0.05"/>
      </geometry>
      <material name="silver"/>
    </visual>
    <inertial>
      <origin rpy="0 1.570796327 1.570796327" xyz="0 0 0"/>
      <mass value="0.4"/>
      <inertia ixx=".1" ixy="0.0" ixz="0.0" iyy=".1" iyz="0.0" izz=".1"/>
    </inertial>
  </link>
  <link name="right_front_wheel">
    <collision name="right_front_wheel_collision">
      <origin rpy="0 1.570796327 1.570796327" xyz="0 0 0"/>
      <geometry>
        <cylinder length="0.05" radius="0.05"/>
      </geometry>
    </collision>
    <visual name="right_front_wheel_visual">
      <origin rpy="0 1.570796327 1.570796327" xyz="0 0 0"/>
      <geometry>
        <cylinder length="0.05" radius="0.05"/>
      </geometry>
      <material name="silver"/>
    </visual>
    <inertial>
      <origin rpy="0 1.570796327 1.570796327" xyz="0 0 0"/>
      <mass value="0.4"/>
      <inertia ixx=".1" ixy="0.0" ixz="0.0" iyy=".1" iyz="0.0" izz=".1"/>
    </inertial>
  </link>
  <link name="right_rear_wheel">
    <collision name="right_rear_wheel_collision">
      <origin rpy="0 1.570796327 1.570796327" xyz="0 0 0"/>
      <geometry>
        <cylinder length="0.05" radius="0.05"/>
      </geometry>
    </collision>
    <visual name="right_rear_wheel_visual">
      <origin rpy="0 1.570796327 1.570796327" xyz="0 0 0"/>
      <geometry>
        <cylinder length="0.05" radius="0.05"/>
      </geometry>
      <material name="silver"/>
    </visual>
    <inertial>
      <origin rpy="0 1.570796327 1.570796327" xyz="0 0 0"/>
      <mass value="0.4"/>
      <inertia ixx=".1" ixy="0.0" ixz="0.0" iyy=".1" iyz="0.0" izz=".1"/>
    </inertial>
  </link>
  <joint name="left_front_wheel_hinge" type="continuous">
    <origin rpy="0 0 0" xyz="0.155 0.152 0.051"/>
    <child link="left_front_wheel"/>
    <parent link="base_link"/>
    <axis rpy="0 0 0" xyz="0 1 0"/>
    <limit effort="10000" velocity="1000"/>
    <joint_properties damping="1.0" friction="1.0"/>
  </joint>
  <joint name="left_rear_wheel_hinge" type="continuous">
    <origin rpy="0 0 0" xyz="-0.155 0.152 0.051"/>
    <child link="left_rear_wheel"/>
    <parent link="base_link"/>
    <axis rpy="0 0 0" xyz="0 1 0"/>
    <limit effort="10000" velocity="1000"/>
    <joint_properties damping="1.0" friction="1.0"/>
  </joint>
  <joint name="right_front_wheel_hinge" type="continuous">
    <origin rpy="0 0 0" xyz="0.155 -0.152 0.051"/>
    <child link="right_front_wheel"/>
    <parent link="base_link"/>
    <axis rpy="0 0 0" xyz="0 1 0"/>
    <limit effort="10000" velocity="1000"/>
    <joint_properties damping="1.0" friction="1.0"/>
  </joint>
  <joint name="right_rear_wheel_hinge" type="continuous">
    <origin rpy="0 0 0" xyz="-0.155 -0.152 0.051"/>
    <child link="right_rear_wheel"/>
    <parent link="base_link"/>
    <axis rpy="0 0 0" xyz="0 1 0"/>
    <limit effort="10000" velocity="1000"/>
    <joint_properties damping="1.0" friction="1.0"/>
  </joint>
  <!--##### END WHEELS #############################################################################-->
  <!--##### ARM MOUNT JOINT #############################################################################-->
  <joint name="Arm_mount_joint" type="fixed">
    <parent link="base_link"/>
    <child link="arm_base_link"/>
    <origin rpy="0 0 0" xyz="0 0 0.1"/>
  </joint>
  <!--##### END ARM MOUNT JOINT #############################################################################-->
  <!--##### RPlidar A2 MOUNT JOINT #############################################################################-->
  <joint name="Rplidar_A2_mount_joint" type="fixed">
    <parent link="base_link"/>
    <child link="rplidar"/>
    <origin rpy="0 0 0" xyz="0.13 0 0.08"/>
  </joint>
  <!-- RP_LIDAR -->
  <link name="rplidar">
    <inertial>
      <mass value="1.8362923"/>
      <origin rpy="0 0 0" xyz="0.0000000 0.0000000 -0.01040000"/>
      <inertia ixx="0.0009124" ixy="0.0" ixz="0.0" iyy="0.0009124" iyz="0.0" izz="0.0013154"/>
    </inertial>
    <visual>
      <origin rpy="0 0 0" xyz="0 -0.027 0"/>
      <geometry>
        <mesh filename="package://robot_description/meshes/rplidar_a2/RPlidar_A2.stl.obj" scale="0.001 0.001 0.001"/>
      </geometry>
      <material name="red"/>
    </visual>
    <collision>
      <!--<origin xyz="0 0 0" rpy="0 0 0"/>-->
      <geometry>
        <mesh filename="package://robot_description/meshes/rplidar_a2/RPlidar_A2.stl.obj" scale="0.001 0.001 0.001"/>
      </geometry>
    </collision>
  </link>
  <!--##### END RPlidar A2 MOUNT JOINT #############################################################################-->
  <!--##################################################################################-->
  <link name="arm_base_link">
    <visual>
      <!--<origin rpy="0 0 0" xyz="0 0 0.0"/>-->
      <geometry>
        <mesh filename="package://robot_description/meshes/GeometryCPRMover4/Joint0.obj" scale="0.001 0.001 0.001"/>
      </geometry>
      <material name="black">
        <color rgba="0 0 0 0.8"/>
      </material>
    </visual>
    <collision>
      <origin rpy="0 0 0" xyz="0 0 0"/>
      <geometry>
        <mesh filename="package://robot_description/meshes/GeometryCPRMover4/Joint0Coll.obj" scale="0.001 0.001 0.001"/>
      </geometry>
    </collision>
  </link>
  <link name="geoJoint1">
    <visual>
      <origin rpy="0 0 0" xyz="0 0 0.0"/>
      <geometry>
        <mesh filename="package://robot_description/meshes/GeometryCPRMover4/Joint1.obj" scale="0.001 0.001 0.001"/>
      </geometry>
      <material name="black">
        <color rgba="0 0 0 0.8"/>
      </material>
    </visual>
    <collision>
      <origin rpy="0 0 0" xyz="0 0 0"/>
      <geometry>
        <mesh filename="package://robot_description/meshes/GeometryCPRMover4/Joint1Coll.obj" scale="0.001 0.001 0.001"/>
      </geometry>
    </collision>
  </link>
  <link name="geoJoint2">
    <visual>
      <origin rpy="0 0 0" xyz="0 0 0.0"/>
      <geometry>
        <mesh filename="package://robot_description/meshes/GeometryCPRMover4/Joint2.obj" scale="0.001 0.001 0.001"/>
      </geometry>
      <material name="black">
        <color rgba="0 0 0 0.8"/>
      </material>
    </visual>
    <collision>
      <origin rpy="0 0 0" xyz="0 0 0"/>
      <geometry>
        <mesh filename="package://robot_description/meshes/GeometryCPRMover4/Joint2Coll.obj" scale="0.001 0.001 0.001"/>
      </geometry>
    </collision>
  </link>
  <link name="geoJoint3">
    <visual>
      <origin rpy="0 0 0" xyz="0 0 0.0"/>
      <geometry>
        <mesh filename="package://robot_description/meshes/GeometryCPRMover4/Joint3.obj" scale="0.001 0.001 0.001"/>
      </geometry>
      <material name="black">
        <color rgba="0 0 0 0.8"/>
      </material>
    </visual>
    <collision>
      <origin rpy="0 0 0" xyz="0 0 0"/>
      <geometry>
        <mesh filename="package://robot_description/meshes/GeometryCPRMover4/Joint3Coll.obj" scale="0.001 0.001 0.001"/>
      </geometry>
    </collision>
  </link>
  <link name="geoJoint4">
    <visual>
      <origin rpy="0 0 0" xyz="0 0 0.0"/>
      <geometry>
        <mesh filename="package://robot_description/meshes/GeometryCPRMover4/Joint4.obj" scale="0.001 0.001 0.001"/>
      </geometry>
      <material name="black">
        <color rgba="0 0 0 0.8"/>
      </material>
    </visual>
    <collision>
      <origin rpy="0 0 0" xyz="0 0 0"/>
      <geometry>
        <mesh filename="package://robot_description/meshes/GeometryCPRMover4/Joint4Coll.obj" scale="0.001 0.001 0.001"/>
      </geometry>
    </collision>
  </link>
  <link name="gripperBody">
    <visual>
      <origin rpy="0 0 0" xyz="0 0 0.0"/>
      <geometry>
        <mesh filename="package://robot_description/meshes/GeometryCPRMover4/GripperBase.obj" scale="0.001 0.001 0.001"/>
      </geometry>
      <material name="black">
        <color rgba="0 0 0 0.8"/>
      </material>
    </visual>
    <collision>
      <origin rpy="0 0 0" xyz="0 0 0"/>
      <geometry>
        <mesh filename="package://robot_description/meshes/GeometryCPRMover4/GripperBaseColl.obj" scale="0.001 0.001 0.001"/>
      </geometry>
    </collision>
  </link>
  <link name="gripperFinger1">
    <visual>
      <origin rpy="0 0 0" xyz="0 0 0.0"/>
      <geometry>
        <mesh filename="package://robot_description/meshes/GeometryCPRMover4/GripperFinger.obj" scale="0.001 0.001 0.001"/>
      </geometry>
      <material name="black">
        <color rgba="0 0 0 0.8"/>
      </material>
    </visual>
    <collision>
      <origin rpy="0 0 0" xyz="0 0 0"/>
      <geometry>
        <mesh filename="package://robot_description/meshes/GeometryCPRMover4/GripperFingerColl.obj" scale="0.001 0.001 0.001"/>
      </geometry>
    </collision>
  </link>
  <link name="gripperFinger2">
    <visual>
      <origin rpy="0 0 0" xyz="0 0 0.0"/>
      <geometry>
        <mesh filename="package://robot_description/meshes/GeometryCPRMover4/GripperFinger.obj" scale="0.001 0.001 0.001"/>
      </geometry>
      <material name="black">
        <color rgba="0 0 0 0.8"/>
      </material>
    </visual>
    <collision>
      <origin rpy="0 0 0" xyz="0 0 0"/>
      <geometry>
        <mesh filename="package://robot_description/meshes/GeometryCPRMover4/GripperFingerColl.obj" scale="0.001 0.001 0.001"/>
      </geometry>
    </collision>
  </link>
  <joint name="Joint0" type="continuous">
    <axis xyz="0 0 1"/>
    <parent link="arm_base_link"/>
    <!--changed base_link to arm_base_link-->
    <child link="geoJoint1"/>
    <origin rpy="0 0 0" xyz="0 0 0.158"/>
    <limit effort="100" velocity="30"/>
    <joint_properties damping="0.0" friction="0.0"/>
  </joint>
  <joint name="Joint1" type="continuous">
    <axis xyz="0 1 0"/>
    <parent link="geoJoint1"/>
    <child link="geoJoint2"/>
    <origin rpy="0 0 0" xyz="0 0 0.060"/>
    <limit effort="100" velocity="100"/>
    <joint_properties damping="0.0" friction="0.0"/>
  </joint>
  <joint name="Joint2" type="continuous">
    <axis xyz="0 1 0"/>
    <parent link="geoJoint2"/>
    <child link="geoJoint3"/>
    <origin rpy="0 0 0" xyz="0 0 0.190"/>
    <limit effort="100" velocity="100"/>
    <joint_properties damping="0.0" friction="0.0"/>
  </joint>
  <joint name="Joint3" type="continuous">
    <axis xyz="0 1 0"/>
    <parent link="geoJoint3"/>
    <child link="geoJoint4"/>
    <origin rpy="0 0 0" xyz="0 0 0.220"/>
    <limit effort="100" velocity="100"/>
    <joint_properties damping="0.0" friction="0.0"/>
  </joint>
  <joint name="GripperFixed" type="fixed">
    <parent link="geoJoint4"/>
    <child link="gripperBody"/>
    <origin rpy="0 0 0" xyz="0 0 0.046"/>
  </joint>
  <!--<joint name="Gripper1" type="continuous">
    <axis xyz="1 0 0"/>
    <parent link="gripperBody"/>
    <child link="gripperFinger1"/>
    <origin rpy="0 0 3.141" xyz="0.0 0.01 0.03"/>
    <limit effort="100" velocity="100"/>
    <joint_properties damping="0.0" friction="0.0"/>
  </joint>
<joint name="Gripper2" type="continuous">
    <axis xyz="1 0 0"/>
    <parent link="gripperBody"/>
    <child link="gripperFinger2"/>
     <origin rpy="0 0 0" xyz="0.0 -0.01 0.03"/>
    <limit effort="100" velocity="100"/>
    <joint_properties damping="0.0" friction="0.0"/>
  </joint>-->
  <!-- THIS IS A TEST USING PRISMATIC JOINT AND MIMMIC IN ORDER TO MODEL THE ACTUAL GRIPPER ON THE MOVER4 ARM WE HAVE-->
  <!-- use multiplier =-1  for the second joint doesent work as expected (mirror), so not using it????-->
  <joint name="Gripper1" type="prismatic">
    <parent link="gripperBody"/>
    <child link="gripperFinger1"/>
    <origin rpy="0 0 3.141" xyz="0.0 0.01 0.03"/>
    <axis xyz="0 1 0"/>
    <limit effort="100" lower="0.0" upper="-0.01" velocity="100"/>
    <joint_properties damping="0.0" friction="0.0"/>
  </joint>
  <joint name="Gripper2" type="prismatic">
    <parent link="gripperBody"/>
    <child link="gripperFinger2"/>
    <origin rpy="0 0 0" xyz="0.0 -0.01 0.03"/>
    <axis xyz="0 1 0"/>
    <limit effort="100" lower="-0.0" upper="0.01" velocity="100"/>
    <joint_properties damping="0.0" friction="0.0"/>
    <mimic joint="Gripper1" multiplier="1" offset="0"/>
  </joint>
</robot>
